<?xml version="1.0"?>

<!--name space and start xacro-->
<robot name ="navigation_robot" xmlns:xacro="http://www.ros.org/wiki/xacro">

	<!--Include all required xacro files-->
	<xacro:include filename="$(find simulation_environment)/models/Navigation_Robot/Navigation_robot.gazebo"/>
	<xacro:include filename="$(find simulation_environment)/models/Navigation_Robot/materials.xacro"/>
	<xacro:include filename="$(find simulation_environment)/models/Navigation_Robot/macros.xacro"/>
	<xacro:include filename="$(find simulation_environment)/models/Navigation_Robot/parameters.xacro"/>
	
	<!--Create dummy link-->
	<link name='base_link'>
		<pose>0 0 0 0 0 0</pose>
	</link>
	<joint type="fixed" name="base_link_to_chassis">
		<child link="chassis_link"/>
		<parent link="base_link"/>
	</joint>

	<!--Define the chassis of the robot-->
	<link name='chassis_link'>
		<pose>0 0 0 0 0 0</pose>
		
		<!--Define inertial system for chassis-->
		<inertial>
			<mass value="${m_chassis}"/>
			<xacro:box_inertia m="${m_chassis}" x="${x_chassis}" y="${y_chassis}" z="${z_chassis}"/>
		</inertial>
		
		<!--Define collision sorrounding box -->
		<collision name="collision">
			<origin xyz="0 0 0" rpy="0 0 0"/>
			<geometry>
				<box size="${x_chassis} ${y_chassis} ${z_chassis}"/>
			</geometry>
		</collision>
		
		<!--Define visuals-->
		<visual name="base_link_visual">
			<origin xyz="0 0 0" rpy="0 0 0"/>
			<geometry>
				<box size="${x_chassis} ${y_chassis} ${z_chassis}"/>
			</geometry>
		</visual>
		
		<!--add caster wheel with zero friction-->
		<collision name="caster_collision">
			<origin xyz="${-(r_wheel/2)+x_chassis/2} 0 ${-z_chassis/2}" rpy="0 0 0"/>
			<geometry>
				<sphere radius="${r_wheel/2}"/>
			</geometry>
			<surface>
				<friction>
					<ode>
						<mu>0</mu>
						<mu2>0</mu2>
						<slip1>1.0</slip1>
						<slip2>1.0</slip2>
					</ode>
				</friction>
			</surface>
		</collision>
		
		<!--visuals for wheel-->
		<visual name="caster_visual">
			<origin xyz="${-(r_wheel/2)+x_chassis/2} 0 ${-z_chassis/2}" rpy="0 0 0"/>
			<geometry>
				<sphere radius="${r_wheel/2}"/>
			</geometry>
		</visual>
	</link>

	<!--add left wheel-->
	<link name="left_wheel">
		<collision>
			<origin xyz="0 0 0" rpy="0 1.5707 1.5707"/>
			<geometry>
				<cylinder radius="${r_wheel}" length="${h_wheel}"/>
			</geometry>
			<surface>
				<friction>
					<ode>
						<mu>0</mu>
						<mu2>0</mu2>
						<slip1>1.0</slip1>
						<slip2>1.0</slip2>
					</ode>
				</friction>
			</surface>
		</collision>
		
		<!--visual for the left wheel-->
		<visual name="left_wheel_visual">
			<origin xyz="0 0 0" rpy="0 1.5707 1.5707"/>
			<geometry>
				<cylinder radius="${r_wheel}" length="${h_wheel}"/>
			</geometry>
		</visual>
		
		<!--inerti for the left wheel-->
		<inertial>
			<origin xyz="0 0 0" rpy="0 1.5707 1.5707"/>
			<mass value="${m_wheel}"/>
			<cylinder_inertia m="${m_wheel}" r="${r_wheel}" h="${h_wheel}"/>
			<xacro:cylinder_inertia m="${m_wheel}" r="${r_wheel}" h="${h_wheel}"/>
		</inertial>
	</link>
	
	<!--add right wheel-->
	<link name="right_wheel">
		<collision>
			<origin xyz="0 0 0" rpy="0 1.5707 1.5707"/>
			<geometry>
				<cylinder radius="${r_wheel}" length="${h_wheel}"/>
			</geometry>
			<surface>
				<friction>
					<ode>
						<mu>0</mu>
						<mu2>0</mu2>
						<slip1>1.0</slip1>
						<slip2>1.0</slip2>
					</ode>
				</friction>
			</surface>
		</collision>
		
		<!--visual for the right wheel-->
		<visual name="left_wheel_visual">
			<origin xyz="0 0 0" rpy="0 1.5707 1.5707"/>
			<geometry>
				<cylinder radius="${r_wheel}" length="${h_wheel}"/>
			</geometry>
		</visual>
		
		<!--inerti for the right wheel-->
		<inertial>
			<origin xyz="0 0 0" rpy="0 1.5707 1.5707"/>
			<mass value="${m_wheel}"/>
			<cylinder_inertia m="${m_wheel}" r="${r_wheel}" h="${h_wheel}"/>
			<xacro:cylinder_inertia m="${m_wheel}" r="${r_wheel}" h="${h_wheel}"/>
		</inertial>
	</link>
	
	<!--Set joints for the wheel to control with ROS-->
	<joint type="continuous" name="left_wheel_hinge">
		<origin xyz="${-x_chassis/4} ${y_chassis/2+h_wheel/2} ${r_wheel/2-z_chassis/2}" rpy="0 0 0"/>
		<child link="left_wheel"/>
		<parent link="base_link"/>
		<axis xyz="0 1 0" rpy="0 0 0"/>
		<limit effort="100" velocity="100"/>
		<joint_properties damping="0.0" friction="0.0"/>
	</joint>
	
	<joint type="continuous" name="right_wheel_hinge">
		<origin xyz="${-x_chassis/4} ${-y_chassis/2-h_wheel/2} ${r_wheel/2-z_chassis/2}" rpy="0 0 0"/>
		<child link="right_wheel"/>
		<parent link="base_link"/>
		<axis xyz="0 1 0" rpy="0 0 0"/>
		<limit effort="100" velocity="100"/>
		<joint_properties damping="0.0" friction="0.0"/>
	</joint>

	<!--add a hokuyo laser-->
	<link name="laser_link">
		<collision>
			<origin xyz="0 0 0" rpy="0 0 0"/>
			<geometry>
				<box size="${x_hokuyo} ${y_hokuyo} ${z_hokuyo}"/>
			</geometry>
		</collision>
		<visual>
			<origin xyz="0 0 0" rpy="0 0 0"/>
			<geometry>
				<box size="${x_hokuyo} ${y_hokuyo} ${z_hokuyo}"/>
			</geometry>
		</visual>
		<inertial>
			<mass value="1e-5"/>
			<origin xyz="0 0 0" rpy="0 0 0"/>
			<inertia ixx="1e-6" ixy="0" ixz="0" iyy="1e-6" iyz="0" izz="1e-6"/>
		</inertial>
	</link>

	<joint name="hokuyo_joint" type="fixed">
		<axis xyz="0 1 0"/>
		<origin xyz="0 0 ${z_chassis/2+z_hokuyo/2}" rpy="0 0 0"/>
		<parent link="base_link"/>
		<child link="laser_link"/>
	</joint>

</robot>
